Workbook

Sheet 📊 Wealth Dashboard
B2: 💼 VIVEK'S PERSONAL WEALTH DASHBOARD | All values pull from Assumptions & Trackers automatically
B4: Age: 32 | Bangkok, Thailand | NRI | Baby due: Early 2027 | India return: 2028-29 | F4: 🎯 FI Target: Age 50 (2043) | FI Corpus: ₹6 Crore | Family Obligations: ₹20L reserved
B6: 💰 NET WORTH (₹) | D6: 🏠 HOME LOAN BALANCE | F6: 📈 MF PORTFOLIO | H6: 📌 KEY METRICS
B7: ='⚙️ Assumptions'!C9+'⚙️ Assumptions'!C33+'⚙️ Assumptions'!C36+'⚙️ Assumptions'!C34+'⚙️ Assumptions'!C35-'⚙️ Assumptions'!C28 -> 5389406 | D7: ='🏠 Home Loan Tracker'!I9 | F7: ='⚙️ Assumptions'!C33 -> 1065000 | H7: Home Loan Remaining Months | I7: ='🏠 Home Loan Tracker'!C316 -> 15-Sep-2049 | J7: months
B8: Assets minus all liabilities | D8: Live from monthly tracker | F8: 22 funds → consolidate to 5 | H8: Home Loan Closure (est.) | I8: ='🏠 Home Loan Tracker'!C317 -> 15-Oct-2049 | J8: date
H9: Family Obligation Reserved | I9: ='⚙️ Assumptions'!C10+'⚙️ Assumptions'!C11 -> 2000000 | J9: ₹
B10: 💵 MONTHLY SURPLUS | D10: 💲 MONTHLY SIP | F10: 📊 FI PROGRESS | H10: Real Estate Appreciation | I10: ='⚙️ Assumptions'!C18 -> 0.035 | J10: % p.a.
B11: ='⚙️ Assumptions'!C26-57000-32000-86000 -> 92000 | D11: ='⚙️ Assumptions'!C37 -> 75000 | F11: =IFERROR(('⚙️ Assumptions'!C9+'⚙️ Assumptions'!C33+'⚙️ Assumptions'!C35-'⚙️ Assumptions'!C28)*100/'⚙️ Assumptions'!C38,0)&"%" -> 8.77401% | H11: MF CAGR Assumption | I11: ='⚙️ Assumptions'!C17 -> 0.12 | J11: % p.a.
B12: After all costs; pre-investment | D12: Equity + Liquid funds | F12: % of ₹6Cr FI corpus | H12: Inflation Assumption | I12: ='⚙️ Assumptions'!C16 -> 0.06 | J12: % p.a.
H13: Emergency Fund | I13: ='⚙️ Assumptions'!C36 -> 45000 | J13: ₹
B14: 📂 ASSET BREAKDOWN (auto-updates from Assumptions sheet) | H14: Emergency Fund Target | I14: 300000 | J14: ₹
B15: Asset / Liability | C15: Current Value (₹) | D15: % of Assets | E15: Notes | F15: Action | H15: Monthly SIP | I15: ='⚙️ Assumptions'!C37 -> 75000 | J15: ₹/mo
B16: Mumbai Flat (Market Value) | C16: ='⚙️ Assumptions'!C9 -> 11000000 | D16: Edit in Assumptions | E16: Update annually | H16: FI Corpus Target | I16: ='⚙️ Assumptions'!C38 -> 60000000 | J16: ₹
B17: Purchase Price (2020) | C17: ='⚙️ Assumptions'!C8 -> 11000000 | D17: Reference only | E17: ₹1.10 Cr; appreciation = Market - Purchase | H17: Years to FI | I17: ='⚙️ Assumptions'!C6-'⚙️ Assumptions'!C5 -> 18 | J17: years
B18: Appreciation Gain | C18: ='⚙️ Assumptions'!C9-'⚙️ Assumptions'!C8 -> 0 | D18: Paper gain | E18: Taxable if sold
B19: Home Loan (LIABILITY) | C19: =-'⚙️ Assumptions'!C28 -> -6860594 | D19: Negative | E19: SBI floating 9.45%
B20: Net Real Estate | C20: ='⚙️ Assumptions'!C9-'⚙️ Assumptions'!C28 -> 4139406 | D20: Net equity | H20: 👨‍👩‍👦 FAMILY OBLIGATIONS TRACKER
B21: Mutual Funds | C21: ='⚙️ Assumptions'!C33 -> 1065000 | D21: Growth engine | E21: Consolidate 22→5 | H21: Brother's House Down Payment | I21: ='⚙️ Assumptions'!C10 -> 1000000 | J21: ⏳ Pending
B22: PPF | C22: ='⚙️ Assumptions'!C34 -> 80000 | D22: ⚠️ Check NRI status | E22: May need to freeze | F22: ⚠️ Action needed | H22: Father's Village House | I22: ='⚙️ Assumptions'!C11 -> 1000000 | J22: ⏳ Pending
B23: NPS Tier 1 | C23: ='⚙️ Assumptions'!C35 -> 60000 | D23: Locked till 60 | E23: Review: continue or stop? | F23: ⚠️ Action needed | H23: TOTAL OBLIGATION | I23: ='⚙️ Assumptions'!C10+'⚙️ Assumptions'!C11 -> 2000000 | J23: 🚨 Set aside NOW
B24: Emergency FD | C24: ='⚙️ Assumptions'!C36 -> 45000 | D24: Too low | E24: Target ₹3L | F24: ✅ OK
B25: Family Obligation – Brother | C25: -'⚙️ Assumptions'!C10 | D25: Reserved outflow | E25: Pay ~'⚙️ Assumptions'!C12
B26: Family Obligation – Father | C26: -'⚙️ Assumptions'!C11 | D26: Reserved outflow | E26: Pay ~'⚙️ Assumptions'!C13
B27: 🏆 NET WORTH (excl. family obligations) | D27: ='⚙️ Assumptions'!C9+'⚙️ Assumptions'!C33+'⚙️ Assumptions'!C34+'⚙️ Assumptions'!C35+'⚙️ Assumptions'!C36-'⚙️ Assumptions'!C28 -> 5389406 | E27: ₹20L family obligations are tracked above separately
B29: 💸 MONTHLY CASH FLOW
B30: INCOME | C30: ₹/month | D30: EXPENSES | E30: ₹/month | F30: Status
B31: Bangkok Salary (in-hand) | C31: ='⚙️ Assumptions'!C26 -> 267000 | D31: Total India Expenses | E31: =57000+12000+20000+2000+2000+5000 -> 98000
B32: Rental Income (from Jan 2027) | C32: ='⚙️ Assumptions'!C27 -> 38000 | D32: Total Bangkok Expenses | E32: =40000+8000+1500+1000+15000+8000+3000+3000+5000 -> 84500
D33: SIPs & Investments | E33: ='⚙️ Assumptions'!C37 -> 75000
B34: 🟢 NET MONTHLY SURPLUS (before SIPs) | E34: ='⚙️ Assumptions'!C26-57000-32000-86000 -> 92000
B36: ⚡ All values auto-pull from ⚙️ Assumptions sheet | Blue = inputs | Update Assumptions → this dashboard updates automatically

Sheet 📅 Year-on-Year Roadmap
B2: 📅 YEAR-ON-YEAR FINANCIAL ROADMAP | Age 32→50 | All assumptions drive from ⚙️ Assumptions sheet
B4: ⚙️ KEY ASSUMPTIONS (edit in Assumptions sheet → all rows update)
B5: Inflation | C5: ='⚙️ Assumptions'!C16 -> 0.06
B6: MF CAGR | C6: ='⚙️ Assumptions'!C17 -> 0.12
B7: RE Appreciation | C7: ='⚙️ Assumptions'!C18 -> 0.035
B8: SIP Step-up | C8: ='⚙️ Assumptions'!C21 -> 0.1
B9: Salary Growth (Bangkok) | C9: ='⚙️ Assumptions'!C19 -> 0.05
B10: Salary Growth (India) | C10: ='⚙️ Assumptions'!C20 -> 0.08
B12: Year | C12: Age | D12: Life Phase & Events | E12: Gross Income (₹/yr) | F12: Expenses (₹/yr) | G12: Net Surplus (₹/yr) | H12: Monthly SIP (₹) | I12: MF Corpus (₹) | J12: RE Value (₹) | K12: Home Loan (₹) | L12: Net Worth (₹) | M12: FI Progress %
B13: 2026 | C13: 32 | D13: 🌏 Bangkok | PPF Review | MF Consolidation Start | E13: ='⚙️ Assumptions'!C26*12 -> 3204000 | F13: =2120000*(1+'⚙️ Assumptions'!C16)^0 -> 2120000 | G13: =E13-F13 -> 1084000 | H13: ='⚙️ Assumptions'!C37 -> 75000 | I13: ='⚙️ Assumptions'!C33*(1+'⚙️ Assumptions'!C17)+H13*12 -> 2092800 | J13: ='⚙️ Assumptions'!C9*(1+'⚙️ Assumptions'!C18) -> 11385000 | K13: =MAX(0,'⚙️ Assumptions'!C28-('⚙️ Assumptions'!C32*12-'⚙️ Assumptions'!C28*'⚙️ Assumptions'!C22)) -> 6673481.4 | L13: =I13+J13-K13+'⚙️ Assumptions'!C34+'⚙️ Assumptions'!C35+'⚙️ Assumptions'!C36 -> 6989318.6 | M13: =IFERROR(L13/'⚙️ Assumptions'!C38,0) -> 0.11648864
B14: 2027 | C14: 33 | D14: 👶 Baby Arrives | Rental ₹38K starts | SIP Step-up | E14: ='⚙️ Assumptions'!C26*12*(1+'⚙️ Assumptions'!C19)^1+'⚙️ Assumptions'!C27*12 -> 3820200 | F14: =2120000*(1+'⚙️ Assumptions'!C16)^1 -> 2247200 | G14: =E14-F14 -> 1573000 | H14: =H13*(1+'⚙️ Assumptions'!C21) -> 82500 | I14: =I13*(1+'⚙️ Assumptions'!C17)+H14*12 -> 3333936 | J14: =J13*(1+'⚙️ Assumptions'!C18) -> 11783475 | K14: =MAX(0,K13-('⚙️ Assumptions'!C32*12-K13*'⚙️ Assumptions'!C22)) -> 6472709.5 | L14: =I14+J14-K14+'⚙️ Assumptions'!C34+'⚙️ Assumptions'!C35+'⚙️ Assumptions'!C36 -> 8829701.5 | M14: =IFERROR(L14/'⚙️ Assumptions'!C38,0) -> 0.14716169
B15: 2028 | C15: 34 | D15: 📈 SIP Boost | Brother obligation ₹10L | Prepayments | E15: ='⚙️ Assumptions'!C26*12*(1+'⚙️ Assumptions'!C19)^2+'⚙️ Assumptions'!C27*12 -> 3988410 | F15: =2120000*(1+'⚙️ Assumptions'!C16)^2+'⚙️ Assumptions'!C10 -> 3382032 | G15: =E15-F15 -> 606378 | H15: =H14*(1+'⚙️ Assumptions'!C21) -> 90750 | I15: =I14*(1+'⚙️ Assumptions'!C17)+H15*12 -> 4823008.3 | J15: =J14*(1+'⚙️ Assumptions'!C18) -> 12195897 | K15: =MAX(0,K14-('⚙️ Assumptions'!C32*12-K14*'⚙️ Assumptions'!C22)) -> 6257281.3 | L15: =I15+J15-K15+'⚙️ Assumptions'!C34+'⚙️ Assumptions'!C35+'⚙️ Assumptions'!C36 -> 10946624 | M15: =IFERROR(L15/'⚙️ Assumptions'!C38,0) -> 0.18244373
B16: 2029 | C16: 35 | D16: 🏠 India Return Planning | Senior PM roles | Last Bangkok year | E16: ='⚙️ Assumptions'!C26*12*(1+'⚙️ Assumptions'!C19)^3+'⚙️ Assumptions'!C27*12 -> 4165030.5 | F16: =2120000*(1+'⚙️ Assumptions'!C16)^3 -> 2524953.9 | G16: =E16-F16 -> 1640076.6 | H16: =H15*(1+'⚙️ Assumptions'!C21) -> 99825 | I16: =I15*(1+'⚙️ Assumptions'!C17)+H16*12 -> 6599669.3 | J16: =J15*(1+'⚙️ Assumptions'!C18) -> 12622753 | K16: =MAX(0,K15-('⚙️ Assumptions'!C32*12-K15*'⚙️ Assumptions'!C22)) -> 6026126.8 | L16: =I16+J16-K16+'⚙️ Assumptions'!C34+'⚙️ Assumptions'!C35+'⚙️ Assumptions'!C36 -> 13381296 | M16: =IFERROR(L16/'⚙️ Assumptions'!C38,0) -> 0.22302159
B17: 2030 | C17: 36 | D17: 🇮🇳 Back to India | ₹35L+ salary | Father obligation ₹10L | E17: =3500000*(1+'⚙️ Assumptions'!C20)^0+'⚙️ Assumptions'!C27*12 -> 3956000 | F17: =2120000*(1+'⚙️ Assumptions'!C16)^4+'⚙️ Assumptions'!C11 -> 3676451.2 | G17: =E17-F17 -> 279548.84 | H17: =H16*(1+'⚙️ Assumptions'!C21) -> 109807.5 | I17: =I16*(1+'⚙️ Assumptions'!C17)+H17*12 -> 8709319.6 | J17: =J16*(1+'⚙️ Assumptions'!C18) -> 13064549 | K17: =MAX(0,K16-('⚙️ Assumptions'!C32*12-K16*'⚙️ Assumptions'!C22)) -> 5778098.1 | L17: =I17+J17-K17+'⚙️ Assumptions'!C34+'⚙️ Assumptions'!C35+'⚙️ Assumptions'!C36 -> 16180771 | M17: =IFERROR(L17/'⚙️ Assumptions'!C38,0) -> 0.26967952
B18: 2031 | C18: 37 | D18: 📊 India Growth Phase | Home loan aggressive prepay | E18: =3500000*(1+'⚙️ Assumptions'!C20)^1+'⚙️ Assumptions'!C27*12 -> 4236000 | F18: =2120000*(1+'⚙️ Assumptions'!C16)^5 -> 2837038.2 | G18: =E18-F18 -> 1398961.8 | H18: =H17*(1+'⚙️ Assumptions'!C21) -> 120788.25 | I18: =I17*(1+'⚙️ Assumptions'!C17)+H18*12 -> 11203897 | J18: =J17*(1+'⚙️ Assumptions'!C18) -> 13521809 | K18: =MAX(0,K17-('⚙️ Assumptions'!C32*12-K17*'⚙️ Assumptions'!C22)) -> 5511963.2 | L18: =I18+J18-K18+'⚙️ Assumptions'!C34+'⚙️ Assumptions'!C35+'⚙️ Assumptions'!C36 -> 19398742 | M18: =IFERROR(L18/'⚙️ Assumptions'!C38,0) -> 0.32331237
B19: 2032 | C19: 38 | D19: 🏡 Property Decision: hold/sell Mumbai flat? | E19: =3500000*(1+'⚙️ Assumptions'!C20)^2+'⚙️ Assumptions'!C27*12 -> 4538400 | F19: =2120000*(1+'⚙️ Assumptions'!C16)^6 -> 3007260.5 | G19: =E19-F19 -> 1531139.5 | H19: =H18*(1+'⚙️ Assumptions'!C21) -> 132867.08 | I19: =I18*(1+'⚙️ Assumptions'!C17)+H19*12 -> 14142770 | J19: =J18*(1+'⚙️ Assumptions'!C18) -> 13995072 | K19: =MAX(0,K18-('⚙️ Assumptions'!C32*12-K18*'⚙️ Assumptions'!C22)) -> 5226400.6 | L19: =I19+J19-K19+'⚙️ Assumptions'!C34+'⚙️ Assumptions'!C35+'⚙️ Assumptions'!C36 -> 23096441 | M19: =IFERROR(L19/'⚙️ Assumptions'!C38,0) -> 0.38494068
B20: 2033 | C20: 39 | D20: 🎓 Child Education Fund | SIP ₹1.5L+/month | E20: =3500000*(1+'⚙️ Assumptions'!C20)^3+'⚙️ Assumptions'!C27*12 -> 4864992 | F20: =2120000*(1+'⚙️ Assumptions'!C16)^7 -> 3187696.1 | G20: =E20-F20 -> 1677295.9 | H20: =H19*(1+'⚙️ Assumptions'!C21) -> 146153.78 | I20: =I19*(1+'⚙️ Assumptions'!C17)+H20*12 -> 17593747 | J20: =J19*(1+'⚙️ Assumptions'!C18) -> 14484899 | K20: =MAX(0,K19-('⚙️ Assumptions'!C32*12-K19*'⚙️ Assumptions'!C22)) -> 4919991.8 | L20: =I20+J20-K20+'⚙️ Assumptions'!C34+'⚙️ Assumptions'!C35+'⚙️ Assumptions'!C36 -> 27343655 | M20: =IFERROR(L20/'⚙️ Assumptions'!C38,0) -> 0.45572758
B21: 2034 | C21: 40 | D21: 📈 Debt reducing fast | MF ₹40L+ milestone | E21: =3500000*(1+'⚙️ Assumptions'!C20)^4+'⚙️ Assumptions'!C27*12 -> 5217711.4 | F21: =2120000*(1+'⚙️ Assumptions'!C16)^8 -> 3378957.9 | G21: =E21-F21 -> 1838753.4 | H21: =H20*(1+'⚙️ Assumptions'!C21) -> 160769.16 | I21: =I20*(1+'⚙️ Assumptions'!C17)+H21*12 -> 21634227 | J21: =J20*(1+'⚙️ Assumptions'!C18) -> 14991871 | K21: =MAX(0,K20-('⚙️ Assumptions'!C32*12-K20*'⚙️ Assumptions'!C22)) -> 4591215.2 | L21: =I21+J21-K21+'⚙️ Assumptions'!C34+'⚙️ Assumptions'!C35+'⚙️ Assumptions'!C36 -> 32219883 | M21: =IFERROR(L21/'⚙️ Assumptions'!C38,0) -> 0.53699804
B22: 2035 | C22: 41 | D22: 🏦 Home Loan Near Closure | Debt-free horizon visible | E22: =3500000*(1+'⚙️ Assumptions'!C20)^5+'⚙️ Assumptions'!C27*12 -> 5598648.3 | F22: =2120000*(1+'⚙️ Assumptions'!C16)^9 -> 3581695.4 | G22: =E22-F22 -> 2016952.9 | H22: =H21*(1+'⚙️ Assumptions'!C21) -> 176846.08 | I22: =I21*(1+'⚙️ Assumptions'!C17)+H22*12 -> 26352487 | J22: =J21*(1+'⚙️ Assumptions'!C18) -> 15516586 | K22: =MAX(0,K21-('⚙️ Assumptions'!C32*12-K21*'⚙️ Assumptions'!C22)) -> 4238437.9 | L22: =I22+J22-K22+'⚙️ Assumptions'!C34+'⚙️ Assumptions'!C35+'⚙️ Assumptions'!C36 -> 37815635 | M22: =IFERROR(L22/'⚙️ Assumptions'!C38,0) -> 0.63026059
B23: 2036 | C23: 42 | D23: 🚀 Debt Free! | SIP Maximised | Pure accumulation | E23: =3500000*(1+'⚙️ Assumptions'!C20)^6+'⚙️ Assumptions'!C27*12 -> 6010060.1 | F23: =2120000*(1+'⚙️ Assumptions'!C16)^10 -> 3796597.1 | G23: =E23-F23 -> 2213463 | H23: =H22*(1+'⚙️ Assumptions'!C21) -> 194530.68 | I23: =I22*(1+'⚙️ Assumptions'!C17)+H23*12 -> 31849154 | J23: =J22*(1+'⚙️ Assumptions'!C18) -> 16059667 | K23: =MAX(0,K22-('⚙️ Assumptions'!C32*12-K22*'⚙️ Assumptions'!C22)) -> 3859907.9 | L23: =I23+J23-K23+'⚙️ Assumptions'!C34+'⚙️ Assumptions'!C35+'⚙️ Assumptions'!C36 -> 44233913 | M23: =IFERROR(L23/'⚙️ Assumptions'!C38,0) -> 0.73723188
B24: 2037 | C24: 43 | D24: 💼 Career Peak | ₹60L+ income | Wealth compounding | E24: =3500000*(1+'⚙️ Assumptions'!C20)^7+'⚙️ Assumptions'!C27*12 -> 6454384.9 | F24: =2120000*(1+'⚙️ Assumptions'!C16)^11 -> 4024392.9 | G24: =E24-F24 -> 2429992 | H24: =H23*(1+'⚙️ Assumptions'!C21) -> 213983.75 | I24: =I23*(1+'⚙️ Assumptions'!C17)+H24*12 -> 38238857 | J24: =J23*(1+'⚙️ Assumptions'!C18) -> 16621755 | K24: =MAX(0,K23-('⚙️ Assumptions'!C32*12-K23*'⚙️ Assumptions'!C22)) -> 3453745.2 | L24: =I24+J24-K24+'⚙️ Assumptions'!C34+'⚙️ Assumptions'!C35+'⚙️ Assumptions'!C36 -> 51591867 | M24: =IFERROR(L24/'⚙️ Assumptions'!C38,0) -> 0.85986445
B25: 2038 | C25: 44 | D25: 📊 MF ₹1Cr+ milestone | RE fully appreciated | E25: =3500000*(1+'⚙️ Assumptions'!C20)^8+'⚙️ Assumptions'!C27*12 -> 6934255.7 | F25: =2120000*(1+'⚙️ Assumptions'!C16)^12 -> 4265856.5 | G25: =E25-F25 -> 2668399.2 | H25: =H24*(1+'⚙️ Assumptions'!C21) -> 235382.13 | I25: =I24*(1+'⚙️ Assumptions'!C17)+H25*12 -> 45652106 | J25: =J24*(1+'⚙️ Assumptions'!C18) -> 17203517 | K25: =MAX(0,K24-('⚙️ Assumptions'!C32*12-K24*'⚙️ Assumptions'!C22)) -> 3017932.6 | L25: =I25+J25-K25+'⚙️ Assumptions'!C34+'⚙️ Assumptions'!C35+'⚙️ Assumptions'!C36 -> 60022690 | M25: =IFERROR(L25/'⚙️ Assumptions'!C38,0) -> 1.0003782
B26: 2039 | C26: 45 | D26: 🎓 Child college fund mature | Partial withdrawal | E26: =3500000*(1+'⚙️ Assumptions'!C20)^9+'⚙️ Assumptions'!C27*12 -> 7452516.2 | F26: =2120000*(1+'⚙️ Assumptions'!C16)^13 -> 4521807.9 | G26: =E26-F26 -> 2930708.3 | H26: =H25*(1+'⚙️ Assumptions'!C21) -> 258920.34 | I26: =I25*(1+'⚙️ Assumptions'!C17)+H26*12 -> 54237402 | J26: =J25*(1+'⚙️ Assumptions'!C18) -> 17805640 | K26: =MAX(0,K25-('⚙️ Assumptions'!C32*12-K25*'⚙️ Assumptions'!C22)) -> 2550305.6 | L26: =I26+J26-K26+'⚙️ Assumptions'!C34+'⚙️ Assumptions'!C35+'⚙️ Assumptions'!C36 -> 69677736 | M26: =IFERROR(L26/'⚙️ Assumptions'!C38,0) -> 1.1612956
B27: 2040 | C27: 46 | D27: ⚡ Power Accumulation | NW ₹3Cr+ zone | E27: =3500000*(1+'⚙️ Assumptions'!C20)^10+'⚙️ Assumptions'!C27*12 -> 8012237.5 | F27: =2120000*(1+'⚙️ Assumptions'!C16)^14 -> 4793116.4 | G27: =E27-F27 -> 3219121.1 | H27: =H26*(1+'⚙️ Assumptions'!C21) -> 284812.38 | I27: =I26*(1+'⚙️ Assumptions'!C17)+H27*12 -> 64163639 | J27: =J26*(1+'⚙️ Assumptions'!C18) -> 18428837 | K27: =MAX(0,K26-('⚙️ Assumptions'!C32*12-K26*'⚙️ Assumptions'!C22)) -> 2048541.9 | L27: =I27+J27-K27+'⚙️ Assumptions'!C34+'⚙️ Assumptions'!C35+'⚙️ Assumptions'!C36 -> 80728934 | M27: =IFERROR(L27/'⚙️ Assumptions'!C38,0) -> 1.3454822
B28: 2041 | C28: 47 | D28: 🔒 Pre-FI | Shift 20% equity→debt | Consolidate | E28: =3500000*(1+'⚙️ Assumptions'!C20)^11+'⚙️ Assumptions'!C27*12 -> 8616736.5 | F28: =2120000*(1+'⚙️ Assumptions'!C16)^15 -> 5080703.4 | G28: =E28-F28 -> 3536033.1 | H28: =H27*(1+'⚙️ Assumptions'!C21) -> 313293.61 | I28: =I27*(1+'⚙️ Assumptions'!C17)+H28*12 -> 75622799 | J28: =J27*(1+'⚙️ Assumptions'!C18) -> 19073846 | K28: =MAX(0,K27-('⚙️ Assumptions'!C32*12-K27*'⚙️ Assumptions'!C22)) -> 1510149.5 | L28: =I28+J28-K28+'⚙️ Assumptions'!C34+'⚙️ Assumptions'!C35+'⚙️ Assumptions'!C36 -> 93371496 | M28: =IFERROR(L28/'⚙️ Assumptions'!C38,0) -> 1.5561916
B29: 2042 | C29: 48 | D29: 🔒 Final push | NW ₹5Cr+ | Retirement planning | E29: =3500000*(1+'⚙️ Assumptions'!C20)^12+'⚙️ Assumptions'!C27*12 -> 9269595.4 | F29: =2120000*(1+'⚙️ Assumptions'!C16)^16 -> 5385545.6 | G29: =E29-F29 -> 3884049.8 | H29: =H28*(1+'⚙️ Assumptions'!C21) -> 344622.97 | I29: =I28*(1+'⚙️ Assumptions'!C17)+H29*12 -> 88833011 | J29: =J28*(1+'⚙️ Assumptions'!C18) -> 19741431 | K29: =MAX(0,K28-('⚙️ Assumptions'!C32*12-K28*'⚙️ Assumptions'!C22)) -> 932454.42 | L29: =I29+J29-K29+'⚙️ Assumptions'!C34+'⚙️ Assumptions'!C35+'⚙️ Assumptions'!C36 -> 1.0782699e+08 | M29: =IFERROR(L29/'⚙️ Assumptions'!C38,0) -> 1.7971165
B30: 2043 | C30: 49 | D30: 🎯 FINANCIAL INDEPENDENCE @ AGE 50! ₹6Cr+ Corpus | E30: =3500000*(1+'⚙️ Assumptions'!C20)^13+'⚙️ Assumptions'!C27*12 -> 9974683 | F30: =2120000*(1+'⚙️ Assumptions'!C16)^17 -> 5708678.3 | G30: =E30-F30 -> 4266004.7 | H30: =H29*(1+'⚙️ Assumptions'!C21) -> 379085.27 | I30: =I29*(1+'⚙️ Assumptions'!C17)+H30*12 -> 1.04042e+08 | J30: =J29*(1+'⚙️ Assumptions'!C18) -> 20432381 | K30: =MAX(0,K29-('⚙️ Assumptions'!C32*12-K29*'⚙️ Assumptions'!C22)) -> 312587.6 | L30: =I30+J30-K30+'⚙️ Assumptions'!C34+'⚙️ Assumptions'!C35+'⚙️ Assumptions'!C36 -> 1.2434679e+08 | M30: =IFERROR(L30/'⚙️ Assumptions'!C38,0) -> 2.0724465
B33: 2026-29: Foundation | D33: 2030-34: Growth | F33: 2035-39: Acceleration | H33: 2040-43: Pre-FI | J33: 2043: FI ACHIEVED! 🎯

Sheet 📈 MF Portfolio
B2: 📈 MUTUAL FUND PORTFOLIO TRACKER | 22 → 5 Fund Consolidation Plan
B4: Fund Name | C4: Category | D4: Invested (₹) | E4: Current (₹) | F4: Gain/Loss (₹) | G4: XIRR % | H4: SIP/month (₹)
B5: ✅ KEEP — TARGET 5-FUND PORTFOLIO
B6: Parag Parikh Flexi Cap | C6: Flexi Cap — CORE | D6: 150000 | E6: 185000 | F6: =E6-D6 -> 35000 | G6: =IFERROR((E6-D6)/D6,0) -> 0.23333333 | H6: 25000
B7: ICICI Pru Bluechip | C7: Large Cap — STABLE | D7: 80000 | E7: 98000 | F7: =E7-D7 -> 18000 | G7: =IFERROR((E7-D7)/D7,0) -> 0.225 | H7: 0
B8: HDFC Mid Cap Opp | C8: Mid Cap — GROWTH | D8: 90000 | E8: 115000 | F8: =E8-D8 -> 25000 | G8: =IFERROR((E8-D8)/D8,0) -> 0.27777778 | H8: 20000
B9: Kotak Small Cap | C9: Small Cap — HIGH GROWTH | D9: 60000 | E9: 80000 | F9: =E9-D9 -> 20000 | G9: =IFERROR((E9-D9)/D9,0) -> 0.33333333 | H9: 0
B10: Parag Parikh Liquid | C10: Liquid — PARKING/EMERGENCY | D10: 100000 | E10: 102000 | F10: =E10-D10 -> 2000 | G10: =IFERROR((E10-D10)/D10,0) -> 0.02 | H10: 20000
B11: ✅ KEEP TOTAL | D11: =SUM(D6:D10) -> 480000 | E11: =SUM(E6:E10) -> 580000 | F11: =E11-D11 -> 100000 | H11: =SUM(H6:H10) -> 65000
B13: ❌ EXIT — 17 FUNDS TO REDEEM (Fill in your details — Blue = enter values)
B14: Fund 1 — Enter Fund Name | C14: (Enter Category) | D14: 0 | E14: 0 | F14: =E14-D14 -> 0 | G14: =IFERROR((E14-D14)/D14,0) -> 0 | H14: 0
B15: Fund 2 — Enter Fund Name | C15: (Enter Category) | D15: 0 | E15: 0 | F15: =E15-D15 -> 0 | G15: =IFERROR((E15-D15)/D15,0) -> 0 | H15: 0
B16: Fund 3 — Enter Fund Name | C16: (Enter Category) | D16: 0 | E16: 0 | F16: =E16-D16 -> 0 | G16: =IFERROR((E16-D16)/D16,0) -> 0 | H16: 0
B17: Fund 4 — Enter Fund Name | C17: (Enter Category) | D17: 0 | E17: 0 | F17: =E17-D17 -> 0 | G17: =IFERROR((E17-D17)/D17,0) -> 0 | H17: 0
B18: Fund 5 — Enter Fund Name | C18: (Enter Category) | D18: 0 | E18: 0 | F18: =E18-D18 -> 0 | G18: =IFERROR((E18-D18)/D18,0) -> 0 | H18: 0
B19: Fund 6 — Enter Fund Name | C19: (Enter Category) | D19: 0 | E19: 0 | F19: =E19-D19 -> 0 | G19: =IFERROR((E19-D19)/D19,0) -> 0 | H19: 0
B20: Fund 7 — Enter Fund Name | C20: (Enter Category) | D20: 0 | E20: 0 | F20: =E20-D20 -> 0 | G20: =IFERROR((E20-D20)/D20,0) -> 0 | H20: 0
B21: Fund 8 — Enter Fund Name | C21: (Enter Category) | D21: 0 | E21: 0 | F21: =E21-D21 -> 0 | G21: =IFERROR((E21-D21)/D21,0) -> 0 | H21: 0
B22: Fund 9 — Enter Fund Name | C22: (Enter Category) | D22: 0 | E22: 0 | F22: =E22-D22 -> 0 | G22: =IFERROR((E22-D22)/D22,0) -> 0 | H22: 0
B23: Fund 10 — Enter Fund Name | C23: (Enter Category) | D23: 0 | E23: 0 | F23: =E23-D23 -> 0 | G23: =IFERROR((E23-D23)/D23,0) -> 0 | H23: 0
B24: Fund 11 — Enter Fund Name | C24: (Enter Category) | D24: 0 | E24: 0 | F24: =E24-D24 -> 0 | G24: =IFERROR((E24-D24)/D24,0) -> 0 | H24: 0
B25: Fund 12 — Enter Fund Name | C25: (Enter Category) | D25: 0 | E25: 0 | F25: =E25-D25 -> 0 | G25: =IFERROR((E25-D25)/D25,0) -> 0 | H25: 0
... B30: Fund 17 — Enter Fund Name | C30: (Enter Category) | D30: 0 | E30: 0 | F30: =E30-D30 -> 0 | G30: =IFERROR((E30-D30)/D30,0) -> 0 | H30: 0
B31: ❌ EXIT TOTAL | D31: =SUM(D14:D30) -> 0 | E31: =SUM(E14:E30) -> 0 | F31: =E31-D31 -> 0
B32: 🏆 GRAND TOTAL | D32: =D11+D31 -> 480000 | E32: =E11+E31 -> 580000 | F32: =E32-D32 -> 100000 | H32: =H11 -> 65000

Sheet 🗓️ Monthly Tracker
B2: 🗓️ DETAILED MONTHLY FINANCIAL TRACKER | FY 2026-27 | Blue = enter actuals each month
B4: Sec | C4: Line Item | D4: Apr-26 | E4: May-26 | F4: Jun-26 | G4: Jul-26 | H4: Aug-26 | I4: Sep-26 | J4: Oct-26 | K4: Nov-26 | L4: Dec-26 | M4: Jan-27 | N4: Feb-27 | O4: Mar-27 | P4: TOTAL | Q4: ✅ Apr-26 Paid?
B6: 💰 INCOME
B7: 💰 | C7: Bangkok Salary (in-hand) | D7: 267000 | E7: 267000 | F7: 267000 | G7: 267000 | H7: 267000 | I7: 267000 | J7: 267000 | K7: 267000 | L7: 267000 | M7: 267000 | N7: 267000 | O7: 267000 | P7: =SUM(D7:O7) -> 3204000
B8: 💰 | C8: Rental Income | D8: 0 | E8: 0 | F8: 0 | G8: 0 | H8: 0 | I8: 0 | J8: 0 | K8: 0 | L8: 0 | M8: 38000 | N8: 38000 | O8: 38000 | P8: =SUM(D8:O8) -> 114000 | Q8: ⏳
B9: 💰 | C9: Bangkok → India Transfer (THB) | D9: 60000 | E9: 60000 | F9: 60000 | G9: 60000 | H9: 60000 | I9: 60000 | J9: 60000 | K9: 60000 | L9: 60000 | M9: 60000 | N9: 60000 | O9: 60000 | P9: =SUM(D9:O9) -> 720000
B10: 💰 | C10: Exchange Rate (1 THB = ? INR) | D10: 2.84 | E10: 2.84 | F10: 2.84 | G10: 2.84 | H10: 2.84 | I10: 2.84 | J10: 2.84 | K10: 2.84 | L10: 2.84 | M10: 2.84 | N10: 2.84 | O10: 2.84 | P10: Update monthly
B11: 💰 | C11: Transfer Value in ₹ (auto-calc) | D11: =ROUND(D9*D10,0) -> 170400 | E11: =ROUND(E9*E10,0) -> 170400 | F11: =ROUND(F9*F10,0) -> 170400 | G11: =ROUND(G9*G10,0) -> 170400 | H11: =ROUND(H9*H10,0) -> 170400 | I11: =ROUND(I9*I10,0) -> 170400 | J11: =ROUND(J9*J10,0) -> 170400 | K11: =ROUND(K9*K10,0) -> 170400 | ... O11: =ROUND(O9*O10,0) -> 170400 | P11: =SUM(D11:O11) -> 2044800
B12: 💰 | C12: Other / Bonus | D12: 0 | E12: 0 | F12: 0 | G12: 0 | H12: 0 | I12: 0 | J12: 0 | K12: 0 | L12: 0 | M12: 0 | N12: 0 | O12: 0 | P12: =SUM(D12:O12) -> 0
B13: TOTAL INCOME | D13: =D7+D8+D11+D12 -> 437400 | E13: =E7+E8+E11+E12 -> 437400 | F13: =F7+F8+F11+F12 -> 437400 | G13: =G7+G8+G11+G12 -> 437400 | H13: =H7+H8+H11+H12 -> 437400 | I13: =I7+I8+I11+I12 -> 437400 | J13: =J7+J8+J11+J12 -> 437400 | K13: =K7+K8+K11+K12 -> 437400 | ... O13: =O7+O8+O11+O12 -> 475400 | P13: =SUM(D13:O13) -> 5362800
B15: 🇮🇳 INDIA EXPENSES
B16: 🇮🇳 | C16: Home Loan EMI | D16: 57328 | E16: 57328 | F16: 57328 | G16: 57328 | H16: 57328 | I16: 57328 | J16: 57328 | K16: 57328 | L16: 57328 | M16: 57328 | N16: 57328 | O16: 57328 | P16: =SUM(D13:O13) -> 5362800 | Q16: ⏳
B17: 🇮🇳 | C17: Maintenance (Society) | D17: 13040 | E17: 13040 | F17: 13040 | G17: 13040 | H17: 13040 | I17: 13040 | J17: 13040 | K17: 13040 | L17: 13040 | M17: 13040 | N17: 13040 | O17: 13040 | P17: =SUM(D14:O14) -> 0 | Q17: ⏳
B18: 🇮🇳 | C18: Term Insurance – Vivek (ICICI) | D18: 1544 | E18: 1544 | F18: 1544 | G18: 1544 | H18: 1544 | I18: 1544 | J18: 1544 | K18: 1544 | L18: 1544 | M18: 1544 | N18: 1544 | O18: 1544 | P18: =SUM(D15:O15) -> 0 | Q18: ⏳
B19: 🇮🇳 | C19: Term Insurance – Wife (ICICI) | D19: 1163 | E19: 1163 | F19: 1163 | G19: 1163 | H19: 1163 | I19: 1163 | J19: 1163 | K19: 1163 | L19: 1163 | M19: 1163 | N19: 1163 | O19: 1163 | P19: =SUM(D16:O16) -> 687936 | Q19: ⏳
B20: 🇮🇳 | C20: Health Insurance (Family) | D20: 5121 | E20: 5121 | F20: 5121 | G20: 5121 | H20: 5121 | I20: 5121 | J20: 5121 | K20: 5121 | L20: 5121 | M20: 5121 | N20: 5121 | O20: 5121 | P20: =SUM(D17:O17) -> 156480 | Q20: ⏳
B21: 🇮🇳 | C21: Additional | D21: 7000 | E21: 0 | F21: 0 | G21: 0 | H21: 0 | I21: 0 | J21: 0 | K21: 0 | L21: 0 | M21: 0 | N21: 0 | O21: 0 | P21: =SUM(D18:O18) -> 18528
B22: 🇮🇳 | C22: Light Bill / Gas / Utilities | D22: 2500 | E22: 2500 | F22: 2500 | G22: 2500 | H22: 2500 | I22: 2500 | J22: 2500 | K22: 2500 | L22: 2500 | M22: 2500 | N22: 2500 | O22: 2500 | P22: =SUM(D19:O19) -> 13956 | Q22: ⏳
B23: 🇮🇳 | C23: Tatya (Grandpa Support) | D23: 2000 | E23: 5000 | F23: 5000 | G23: 5000 | H23: 5000 | I23: 5000 | J23: 5000 | K23: 5000 | L23: 5000 | M23: 5000 | N23: 5000 | O23: 5000 | P23: =SUM(D20:O20) -> 61452 | Q23: ⏳
B24: 🇮🇳 | C24: iCloud Subscription | D24: 749 | E24: 749 | F24: 749 | G24: 749 | H24: 749 | I24: 749 | J24: 749 | K24: 749 | L24: 749 | M24: 749 | N24: 749 | O24: 749 | P24: =SUM(D21:O21) -> 7000 | Q24: ⏳
B25: 🇮🇳 | C25: Miscellaneous | D25: 0 | E25: 0 | F25: 0 | G25: 0 | H25: 0 | I25: 0 | J25: 0 | K25: 0 | L25: 0 | M25: 0 | N25: 0 | O25: 0 | P25: =SUM(D22:O22) -> 30000
B26: 🇮🇳 | C26: Parents' Health Insurance | D26: 6836 | E26: 6836 | F26: 6836 | G26: 6836 | H26: 6836 | I26: 6836 | J26: 6836 | K26: 6836 | L26: 6836 | M26: 6836 | N26: 6836 | O26: 6836 | P26: =SUM(D23:O23) -> 57000 | Q26: ⏳
B27: 🇮🇳 | C27: Credit Card Bill (India) | D27: 3000 | E27: 3000 | F27: 3000 | G27: 3000 | H27: 3000 | I27: 3000 | J27: 3000 | K27: 3000 | L27: 3000 | M27: 3000 | N27: 3000 | O27: 3000 | P27: =SUM(D24:O24) -> 8988
B28: TOTAL INDIA EXPENSES | D28: =SUM(D16:D27) -> 100281 | E28: =SUM(E16:E27) -> 96281 | F28: =SUM(F16:F27) -> 96281 | G28: =SUM(G16:G27) -> 96281 | H28: =SUM(H16:H27) -> 96281 | I28: =SUM(I16:I27) -> 96281 | J28: =SUM(J16:J27) -> 96281 | K28: =SUM(K16:K27) -> 96281 | ... O28: =SUM(O16:O27) -> 96281 | P28: =SUM(D28:O28) -> 1159372
B30: 🇹🇭 BANGKOK EXPENSES
B31: 🇹🇭 | C31: Rent | D31: 29000 | E31: 29000 | F31: 29000 | G31: 29000 | H31: 29000 | I31: 29000 | J31: 29000 | K31: 29000 | L31: 29000 | M31: 29000 | N31: 29000 | O31: 29000 | P31: =SUM(D28:O28) -> 1159372 | Q31: ⏳
B32: 🇹🇭 | C32: Electricity Bill | D32: 2500 | E32: 2500 | F32: 2500 | G32: 2500 | H32: 2500 | I32: 2500 | J32: 2500 | K32: 2500 | L32: 2500 | M32: 2500 | N32: 2500 | O32: 2500 | P32: =SUM(D29:O29) -> 0 | Q32: ⏳
B33: 🇹🇭 | C33: Water Bill | D33: 600 | E33: 600 | F33: 600 | G33: 600 | H33: 600 | I33: 600 | J33: 600 | K33: 600 | L33: 600 | M33: 600 | N33: 600 | O33: 600 | P33: =SUM(D30:O30) -> 0 | Q33: ⏳
B34: 🇹🇭 | C34: WiFi | D34: 2200 | E34: 2200 | F34: 2200 | G34: 2200 | H34: 2200 | I34: 2200 | J34: 2200 | K34: 2200 | L34: 2200 | M34: 2200 | N34: 2200 | O34: 2200 | P34: =SUM(D31:O31) -> 348000 | Q34: ⏳
B35: 🇹🇭 | C35: Mobile Recharge | D35: 1000 | E35: 1000 | F35: 1000 | G35: 1000 | H35: 1000 | I35: 1000 | J35: 1000 | K35: 1000 | L35: 1000 | M35: 1000 | N35: 1000 | O35: 1000 | P35: =SUM(D32:O32) -> 30000 | Q35: ⏳
B36: 🇹🇭 | C36: Grocery | D36: 15000 | E36: 15000 | F36: 15000 | G36: 15000 | H36: 15000 | I36: 15000 | J36: 15000 | K36: 15000 | L36: 15000 | M36: 15000 | N36: 15000 | O36: 15000 | P36: =SUM(D33:O33) -> 7200
B37: 🇹🇭 | C37: Maid | D37: 6000 | E37: 6000 | F37: 6000 | G37: 6000 | H37: 6000 | I37: 6000 | J37: 6000 | K37: 6000 | L37: 6000 | M37: 6000 | N37: 6000 | O37: 6000 | P37: =SUM(D34:O34) -> 26400 | Q37: ⏳
B38: 🇹🇭 | C38: Gym | D38: 3000 | E38: 3000 | F38: 3000 | G38: 3000 | H38: 3000 | I38: 3000 | J38: 3000 | K38: 3000 | L38: 3000 | M38: 3000 | N38: 3000 | O38: 3000 | P38: =SUM(D35:O35) -> 12000 | Q38: ⏳
B39: 🇹🇭 | C39: iPhone EMI | D39: 9000 | E39: 9000 | F39: 9000 | G39: 9000 | H39: 9000 | I39: 9000 | J39: 9000 | K39: 9000 | L39: 9000 | M39: 9000 | N39: 9000 | O39: 9000 | P39: =SUM(D36:O36) -> 180000 | Q39: ⏳
B40: 🇹🇭 | C40: Misc / Outings | P40: =SUM(D37:O37) -> 72000
B41: TOTAL BANGKOK EXPENSES | D41: =SUM(D28:D37) -> 156581 | E41: =SUM(E28:E37) -> 152581 | F41: =SUM(F28:F37) -> 152581 | G41: =SUM(G28:G37) -> 152581 | H41: =SUM(H28:H37) -> 152581 | I41: =SUM(I28:I37) -> 152581 | J41: =SUM(J28:J37) -> 152581 | K41: =SUM(K28:K37) -> 152581 | ... P41: =SUM(P28:P37) -> 2730344
B43: 💎 SAVINGS & INVESTMENTS
B44: 💎 | C44: PP Flexi Cap SIP | D44: 25000 | E44: 25000 | F44: 25000 | G44: 25000 | H44: 25000 | I44: 25000 | J44: 25000 | K44: 25000 | L44: 25000 | M44: 25000 | N44: 25000 | O44: 25000 | P44: =SUM(D41:O41) -> 1834972 | Q44: ⏳
B45: 💎 | C45: HDFC Mid Cap SIP | D45: 20000 | E45: 20000 | F45: 20000 | G45: 20000 | H45: 20000 | I45: 20000 | J45: 20000 | K45: 20000 | L45: 20000 | M45: 20000 | N45: 20000 | O45: 20000 | P45: =SUM(D42:O42) -> 0 | Q45: ⏳
B46: 💎 | C46: PP Liquid SIP | D46: 20000 | E46: 20000 | F46: 20000 | G46: 20000 | H46: 20000 | I46: 20000 | J46: 20000 | K46: 20000 | L46: 20000 | M46: 20000 | N46: 20000 | O46: 20000 | P46: =SUM(D43:O43) -> 0 | Q46: ⏳
...

Sheet 🏠 Home Loan Tracker
B2: 🏠 HOME LOAN MONTHLY AMORTIZATION TRACKER | SBI | ₹68,60,594 Outstanding | 7.30% PA | ₹57,328 EMI
B4: 📌 LOAN FACTS (hardcoded from your SBI statement)
B5: Sanctioned Amount | C5: 7422750 | D5: Jan 2021 — SBI
B6: Outstanding Balance (Apr 2026) | C6: 6860594 | D6: Exact from statement
B7: Principal Repaid so far | C7: 562156 | D7: ₹74,22,750 − ₹68,60,594
B8: % Repaid | C8: =C6/C5 -> 0.9242658 | D8: Only 7.6% paid in 5 yrs — floating rate effect
B9: Current Interest Rate | C9: 0.073 | D9: 7.30% PA (SBI floating — update if changed)
B10: Monthly EMI | C10: 57328 | D10: Debited on 15th of every month
B11: Remaining Tenure | C11: 269 | D11: Months (as of Apr 2026)
B12: Loan Start Date | C12: Jan-2021 | D12: Original disbursement
B13: Estimated Closure (no prepay) | C13: =TEXT(DATE(2026,4+COUNTIF(D35:D334,">0"),1),"MMM-YYYY") -> Mar-2044 | D13: Formula links to amortization count below
B16: ⚠️ WHY DO YOU HAVE 269 MONTHS LEFT AFTER 5 YEARS? — Diagnosis & What To Do
B17: THE PROBLEM
B18: Your loan started in Jan 2021 at ₹74.23L for 240 months (20 years). After 63 EMIs paid, you've only repaid ₹5.62L principal — just 7.6%. On a normal reducing-balance loan you should have paid ~₹12-15L principal by now. The gap is because SBI's floating rate kept RISING (from ~7% in 2021 to 9.45% at peak). When rates rose, your EMI stayed SAME but more of it went to interest, so principal barely moved. This is called 'negative amortization pressure' and it EXTENDS your tenure.
B19: WHAT EXACTLY HAPPENED
B20: Jan 2021: Rate ~7.0% → Monthly Interest on ₹74.23L = ₹43,303 → Principal paid per EMI = ₹14,025
B21: Rate rose to 9.45% peak → Monthly Interest = ₹58,730 on same balance → Your EMI ₹57,328 < Interest! → Principal = NEGATIVE → Bank ADDED to your outstanding balance
B22: This is why after 5 years, 269 months still remain instead of ~177 months
B23: Now at 7.30%: Interest = ₹41,768 on ₹68.6L → Principal per EMI = ₹15,560 → Tenure reducing again ✅
B24: YOUR 3 OPTIONS — What Should You Do?
B25: OPTION 1 ✅ RECOMMENDED: Keep EMI, add ₹10K-20K prepayment monthly → closes ~8-10 years early → saves ₹30-40L interest
B26: OPTION 2: Ask SBI to RESET TENURE to original 240 months → Bank will INCREASE your EMI to ~₹62,000 → Higher monthly cash outflow but loan ends on original 2041 schedule
B27: OPTION 3: Do nothing, continue ₹57,328 EMI → Loan closes ~2048 (269 months from now) → You pay ~₹1.53 Crore total vs ₹74L borrowed → Extra ₹79L in interest
... B33: 📊 MONTHLY AMORTIZATION | Column H = Enter your prepayment → everything updates automatically
B34: # | C34: Due Date | D34: Opening Balance (₹) | E34: EMI (₹57,328) | F34: Interest Charged (₹) | G34: Principal Repaid (₹) | H34: 🔵 Extra Prepayment (₹) ENTER HERE | I34: Closing Balance (₹) | J34: 📌 Status (Paid/Pending)
B35: 1 | C35: 15-Apr-2026 | D35: =C6 -> 6860594 | E35: =IF(D35>0,MIN($C$10,D35+F35),0) -> 57328 | F35: =IF(D35>0,ROUND(D35*$C$9/12,0),0) -> 41735 | G35: =IF(D35>0,MAX(0,E35-F35),0) -> 15593 | H35: 0 | I35: =IF(D35>0,MAX(0,D35-G35-H35),0) -> 6845001 | J35: ✅ Paid
B36: 2 | C36: 15-May-2026 | D36: =IF(I35>0,I35,0) -> 6845001 | E36: =IF(D36>0,MIN($C$10,D36+F36),0) -> 57328 | F36: =IF(D36>0,ROUND(D36*$C$9/12,0),0) -> 41640 | G36: =IF(D36>0,MAX(0,E36-F36),0) -> 15688 | H36: 0 | I36: =IF(D36>0,MAX(0,D36-G36-H36),0) -> 6829313 | J36: ⏳ Pending
B37: 3 | C37: 15-Jun-2026 | D37: =IF(I36>0,I36,0) -> 6829313 | E37: =IF(D37>0,MIN($C$10,D37+F37),0) -> 57328 | F37: =IF(D37>0,ROUND(D37*$C$9/12,0),0) -> 41545 | G37: =IF(D37>0,MAX(0,E37-F37),0) -> 15783 | H37: 0 | I37: =IF(D37>0,MAX(0,D37-G37-H37),0) -> 6813530 | J37: ⏳ Pending
B38: 4 | C38: 15-Jul-2026 | D38: =IF(I37>0,I37,0) -> 6813530 | E38: =IF(D38>0,MIN($C$10,D38+F38),0) -> 57328 | F38: =IF(D38>0,ROUND(D38*$C$9/12,0),0) -> 41449 | G38: =IF(D38>0,MAX(0,E38-F38),0) -> 15879 | H38: 0 | I38: =IF(D38>0,MAX(0,D38-G38-H38),0) -> 6797651 | J38: ⏳ Pending
B39: 5 | C39: 15-Aug-2026 | D39: =IF(I38>0,I38,0) -> 6797651 | E39: =IF(D39>0,MIN($C$10,D39+F39),0) -> 57328 | F39: =IF(D39>0,ROUND(D39*$C$9/12,0),0) -> 41352 | G39: =IF(D39>0,MAX(0,E39-F39),0) -> 15976 | H39: 0 | I39: =IF(D39>0,MAX(0,D39-G39-H39),0) -> 6781675 | J39: ⏳ Pending
B40: 6 | C40: 15-Sep-2026 | D40: =IF(I39>0,I39,0) -> 6781675 | E40: =IF(D40>0,MIN($C$10,D40+F40),0) -> 57328 | F40: =IF(D40>0,ROUND(D40*$C$9/12,0),0) -> 41255 | G40: =IF(D40>0,MAX(0,E40-F40),0) -> 16073 | H40: 0 | I40: =IF(D40>0,MAX(0,D40-G40-H40),0) -> 6765602 | J40: ⏳ Pending
B41: 7 | C41: 15-Oct-2026 | D41: =IF(I40>0,I40,0) -> 6765602 | E41: =IF(D41>0,MIN($C$10,D41+F41),0) -> 57328 | F41: =IF(D41>0,ROUND(D41*$C$9/12,0),0) -> 41157 | G41: =IF(D41>0,MAX(0,E41-F41),0) -> 16171 | H41: 0 | I41: =IF(D41>0,MAX(0,D41-G41-H41),0) -> 6749431 | J41: ⏳ Pending
B42: 8 | C42: 15-Nov-2026 | D42: =IF(I41>0,I41,0) -> 6749431 | E42: =IF(D42>0,MIN($C$10,D42+F42),0) -> 57328 | F42: =IF(D42>0,ROUND(D42*$C$9/12,0),0) -> 41059 | G42: =IF(D42>0,MAX(0,E42-F42),0) -> 16269 | H42: 0 | I42: =IF(D42>0,MAX(0,D42-G42-H42),0) -> 6733162 | J42: ⏳ Pending
B43: 9 | C43: 15-Dec-2026 | D43: =IF(I42>0,I42,0) -> 6733162 | E43: =IF(D43>0,MIN($C$10,D43+F43),0) -> 57328 | F43: =IF(D43>0,ROUND(D43*$C$9/12,0),0) -> 40960 | G43: =IF(D43>0,MAX(0,E43-F43),0) -> 16368 | H43: 0 | I43: =IF(D43>0,MAX(0,D43-G43-H43),0) -> 6716794 | J43: ⏳ Pending
B44: 10 | C44: 15-Jan-2027 | D44: =IF(I43>0,I43,0) -> 6716794 | E44: =IF(D44>0,MIN($C$10,D44+F44),0) -> 57328 | F44: =IF(D44>0,ROUND(D44*$C$9/12,0),0) -> 40860 | G44: =IF(D44>0,MAX(0,E44-F44),0) -> 16468 | H44: 0 | I44: =IF(D44>0,MAX(0,D44-G44-H44),0) -> 6700326 | J44: ⏳ Pending
B45: 11 | C45: 15-Feb-2027 | D45: =IF(I44>0,I44,0) -> 6700326 | E45: =IF(D45>0,MIN($C$10,D45+F45),0) -> 57328 | F45: =IF(D45>0,ROUND(D45*$C$9/12,0),0) -> 40760 | G45: =IF(D45>0,MAX(0,E45-F45),0) -> 16568 | H45: 0 | I45: =IF(D45>0,MAX(0,D45-G45-H45),0) -> 6683758 | J45: ⏳ Pending
B46: 12 | C46: 15-Mar-2027 | D46: =IF(I45>0,I45,0) -> 6683758 | E46: =IF(D46>0,MIN($C$10,D46+F46),0) -> 57328 | F46: =IF(D46>0,ROUND(D46*$C$9/12,0),0) -> 40660 | G46: =IF(D46>0,MAX(0,E46-F46),0) -> 16668 | H46: 0 | I46: =IF(D46>0,MAX(0,D46-G46-H46),0) -> 6667090 | J46: ⏳ Pending
B47: 13 | C47: 15-Apr-2027 | D47: =IF(I46>0,I46,0) -> 6667090 | E47: =IF(D47>0,MIN($C$10,D47+F47),0) -> 57328 | F47: =IF(D47>0,ROUND(D47*$C$9/12,0),0) -> 40558 | G47: =IF(D47>0,MAX(0,E47-F47),0) -> 16770 | H47: 0 | I47: =IF(D47>0,MAX(0,D47-G47-H47),0) -> 6650320 | J47: ⏳ Pending
... B334: 300 | C334: 15-Mar-2051 | D334: =IF(I333>0,I333,0) -> 0 | E334: =IF(D334>0,MIN($C$10,D334+F334),0) -> 0 | F334: =IF(D334>0,ROUND(D334*$C$9/12,0),0) -> 0 | G334: =IF(D334>0,MAX(0,E334-F334),0) -> 0 | H334: 0 | I334: =IF(D334>0,MAX(0,D334-G334-H334),0) -> 0 | J334: ⏳ Pending
B337: 📊 RUNNING TOTALS (auto-updates as you add prepayments or mark payments)
...

Sheet ✅ Planning Checklist
B2: ✅ COMPREHENSIVE FINANCIAL PLANNING CHECKLIST | Vivek 2026-2043
B4: ✓ | C4: Action Item | D4: Priority | E4: Deadline | F4: Notes / Status
B5: 🚨 IMMEDIATE ACTIONS (Apr–Jun 2026)
B6: ☐ | C6: Call SBI: confirm PPF NRI legality → freeze if illegal | D6: 🔴 CRITICAL | E6: May 2026 | F6: May attract penalty if contributions made as NRI
B7: ☐ | C7: Reduce HDFC Liquid SIP: ₹15K → ₹10K | D7: 🔴 CRITICAL | E7: April 2026 | F7: Total SIP = ₹75K within surplus
B8: ☐ | C8: Stop SIPs in 17 non-target funds | D8: 🔴 HIGH | E8: April 2026 | F8: Keep only the 5 in MF tracker
B9: ☐ | C9: Begin redeeming exit MFs in tranches | D9: 🔴 HIGH | E9: May-Aug 2026 | F9: Manage STCG 15% + LTCG 10% above ₹1L
B10: ☐ | C10: Build Emergency Fund to ₹3L | D10: 🟡 MEDIUM | E10: June 2026 | F10: Currently ₹45K only
B11: ☐ | C11: Verify maternity hospital cashless coverage in Bangkok | D11: 🟡 MEDIUM | E11: June 2026 | F11: Check room rent limits, waiting period
B12: ☐ | C12: Update nominees: MFs, NPS, FDs, insurance | D12: 🟡 MEDIUM | E12: May 2026 | F12: Critical with baby on the way
B13: 🛡️ INSURANCE & LEGAL (Jul–Sep 2026)
B14: ☐ | C14: Buy ₹1Cr additional term cover (total → ₹2Cr) | D14: 🔴 HIGH | E14: July 2026 | F14: ~₹8-12K/yr at age 32
B15: ☐ | C15: Draft Will — flat + MFs + NPS | D15: 🟡 MEDIUM | E15: July 2026 | F15: ₹3-5K one-time via lawyer
B16: ☐ | C16: Complete MF consolidation: 22 → 5 funds | D16: 🔴 HIGH | E16: Aug 2026 | F16: Park corpus in PP Liquid during transition
B17: ☐ | C17: Set aside tax on capital gains | D17: 🟡 MEDIUM | E17: Aug 2026 | F17: LTCG 10% above ₹1L; STCG 15%
B18: ☐ | C18: Check SBI home loan balance transfer (7.30% or lower) | D18: 🟢 LOW | E18: Sep 2026 | F18: Current 9.45% is high; negotiate or BT
B19: 🏠 RENTAL & BABY (Oct–Dec 2026)
B20: ☐ | C20: Registered rental agreement for Mumbai flat | D20: 🔴 HIGH | E20: Nov 2026 | F20: 11-month; police verification required
B21: ☐ | C21: Apply Form 13 for lower TDS on rental | D21: 🟡 MEDIUM | E21: Nov 2026 | F21: NRO rental TDS is 30%; apply to reduce
B22: ☐ | C22: Start Baby Fund SIP ₹10K/month | D22: 🟡 MEDIUM | E22: June 2026 | F22: PP Liquid or short-duration debt
B23: ☐ | C23: Confirm cashless maternity in Bangkok hospital | D23: 🔴 HIGH | E23: Oct 2026 | F23: 3 months before expected delivery
B24: 👨‍👩‍👦 FAMILY OBLIGATIONS
B25: ☐ | C25: Start reserving for Brother's obligation (₹10L) | D25: 🟡 MEDIUM | E25: Ongoing | F25: Target 2028; save ~₹4K/month in liquid
B26: ☐ | C26: Start reserving for Father's obligation (₹10L) | D26: 🟡 MEDIUM | E26: Ongoing | F26: Target 2030; save ~₹3K/month in liquid
B27: ☐ | C27: Keep ₹20L family obligation SEPARATE from FI corpus | D27: 🔴 HIGH | E27: Immediately | F27: Do NOT count this in net worth for FI
B28: 📊 TAX & COMPLIANCE
B29: ☐ | C29: File NRI ITR every year (rental + LTCG) | D29: 🔴 CRITICAL | E29: July each year | F29: NRO interest + rental income taxable
B30: ☐ | C30: FEMA compliance for India↔Thailand transfers | D30: 🟡 MEDIUM | E30: Ongoing | F30: Use proper banking channels always
B31: ☐ | C31: Claim DTAA benefit (India-Thailand treaty) | D31: 🟡 MEDIUM | E31: Annual | F31: Avoid double taxation on income
B32: ☐ | C32: NPS: decide continue/stop (see NPS Analysis sheet) | D32: 🟡 MEDIUM | E32: June 2026 | F32: Locked till 60; low flexibility
B33: 🎯 LONG-TERM MILESTONES
B34: ☐ | C34: Home loan prepayment ₹8K+/mo from Jan 2027 | D34: 🟡 MEDIUM | E34: Jan 2027 | F34: Saves ₹8-10L total interest
B35: ☐ | C35: SIP step-up 10% each April | D35: 🟡 MEDIUM | E35: April annually | F35: ₹75K→₹82.5K→₹90.75K...
B36: ☐ | C36: Child education corpus ₹50L by child age 18 | D36: 🟡 MEDIUM | E36: 2027-2045 | F36: ₹10K/month now; ₹50L+ in 18yrs @12%
B37: ☐ | C37: Shift MF: 60% equity → 40% debt by age 45 | D37: 🟡 MEDIUM | E37: ~2038 | F37: De-risk 5 yrs before FI
B38: ☐ | C38: Review FI number every 3 years for inflation | D38: 🟡 MEDIUM | E38: Every 3 yrs | F38: ₹6Cr today = ~₹10Cr in 2043
B39: ☐ | C39: FINANCIAL INDEPENDENCE at Age 50 (2043) | D39: 🎯 DREAM | E39: 2043 | F39: ₹6Cr corpus + ₹38K+ rental = FI
B41: 💡 Change ☐ to ☑ as done | 🔴 Critical = do this week | 🟡 Medium = this quarter | 🟢 Low = next 6 months

Sheet 🔒 NPS Analysis
B2: 🔒 NPS ANALYSIS | Should Vivek Continue or Stop?
B4: WHAT IS NPS?
B5: NPS (National Pension System) is a government-backed retirement scheme. You contribute to Tier 1 (locked till age 60). At 60, you can withdraw 60% tax-free; the remaining 40% must be used to buy an annuity (monthly pension).
B6: YOUR NPS SITUATION
B11: ⚠️ KEY PROBLEM: You plan FI at 50, but NPS is locked till 60. You will have a 10-YEAR GAP where this money is inaccessible. During FI (50-60), you cannot use NPS.
B12: ARGUMENTS FOR CONTINUING NPS
B13: 1. Tax Benefit: Extra ₹50K deduction under 80CCD(1B) saves ~₹15K/year tax
B14: 2. Forced savings: Completely locked — cannot be spent impulsively
B15: 3. Employer NPS: If your employer contributes, that's free money — always accept
B16: 4. ₹60K corpus will grow to ~₹10-15L by age 60 (at 9-10% CAGR) passively
B17: ARGUMENTS AGAINST CONTINUING NPS
B18: 1. LOCKED TILL 60: If FI at 50, NPS money is USELESS for 10 years
... B38: NPS ₹60K today → ~₹8-9L at 60. Not life-changing. Stop contributing. Let it compound. Focus your surplus on MFs which give you freedom at age 50, not 60.

Sheet 💎 Diversification Guide
B2: 💎 SAVINGS DIVERSIFICATION GUIDE | Should You Invest Beyond MFs?
B4: YOUR CURRENT PORTFOLIO CONCENTRATION
B5: You currently have ~95% of investable savings in Mutual Funds. The question is: is that too concentrated? Short answer: At your stage (32, early wealth-building), heavy MF concentration is FINE. But adding 1-2 asset classes STRATEGICALLY improves long-term risk-adjusted returns.
B6: ASSET CLASS ANALYSIS
B7: 🟡 GOLD — Recommended: 5-10% of portfolio
B8: WHY: Gold is negatively correlated with equities — when markets fall, gold usually rises. Acts as insurance. Also performs well during inflation and currency devaluation (important as an NRI with INR exposure).
B9: HOW: Sovereign Gold Bonds (SGBs) — best option. 2.5% annual interest + gold price appreciation + 0% tax if held to maturity (8 years). NOT physical gold, NOT gold ETF (lower tax efficiency). Invest ₹3-5K/month via SGB.
B10: VERDICT: ✅ YES — Add 5% gold allocation via SGBs. ~₹3-5K/month
B11: 🔵 US/INTERNATIONAL STOCKS — Recommended: 10-15% of portfolio
B12: WHY: Your entire portfolio is INR-denominated. If INR depreciates (it has been for decades), your purchasing power vs USD drops. International funds give USD exposure and access to global leaders (Apple, Google, NVIDIA) that India doesn't have.
B13: HOW: Parag Parikh Flexi Cap already has ~35% international exposure — you're partially covered! But you can add Motilal Oswal Nasdaq 100 or ICICI Pru US Bluechip for direct US exposure. SEBI limits overseas MF investments — check current limits before investing.
B14: VERDICT: ✅ PARTIAL — You already have this via PP Flexi Cap. Add ₹5-10K to a dedicated US fund ONLY after SEBI restores overseas investment limits.
... B42: AFTER 2030 (India return, higher salary): Full diversification review with a fee-only advisor

Sheet ⚙️ Assumptions
B2: ⚙️ MASTER ASSUMPTIONS | Change here → all sheets update automatically
B4: 📌 PERSONAL & LIFE
B5: Current Age | C5: 32 | D5: Vivek
B6: FI Target Age | C6: 50 | D6: Financial Independence goal
B7: Current Year | C7: 2026 | D7: Base year
B8: House Purchase Price (₹) | C8: 11000000 | D8: Jan 2020; ₹1.10 Cr
B9: House Current Market Value (₹) | C9: 11000000 | D9: Update annually
B10: Family Obligation – Brother (₹) | C10: 1000000 | D10: Pay when brother buys house
B11: Family Obligation – Father (₹) | C11: 1000000 | D11: Pay when father builds village house
B12: Family Obligation Year – Brother | C12: 2028 | D12: Expected year
B13: Family Obligation Year – Father | C13: 2030 | D13: Expected year
B15: 📈 GROWTH & INFLATION RATES
B16: Inflation Rate | C16: 0.06 | D16: 6% long-term India inflation
B17: MF Portfolio CAGR | C17: 0.12 | D17: 12% equity long-term
B18: Real Estate Appreciation | C18: 0.035 | D18: 3-4% conservative (use 3.5%)
B19: Salary Growth Rate (Bangkok) | C19: 0.05 | D19: 5% per year
B20: Salary Growth Rate (India) | C20: 0.08 | D20: 8% post return
B21: SIP Annual Step-up | C21: 0.1 | D21: 10% increase per year
B22: Home Loan Rate (Current) | C22: 0.073 | D22: 7.30% SBI floating — update if rate changes
B23: Home Loan Rate (Target) | C23: 0.073 | D23: 7.30% if you negotiate down
B25: 💰 CURRENT FINANCIALS
B26: Bangkok Salary In-Hand (₹/mo) | C26: 267000 | D26: 94K THB
B27: Rental Income from Jan 2027 (₹/mo) | C27: 38000 | D27: Mumbai flat
B28: Home Loan Outstanding (₹) | C28: 6860594 | D28: SBI exact balance Apr 2026 (₹68,60,594)
B29: Home Loan Original (₹) | C29: 7422750 | D29: Sanctioned Jan 2021 (₹74,22,750)
B30: Home Loan Start Date | C30: Jan-2021 | D30: Disbursement month
B31: Home Loan Tenure (months) | C31: 269 | D31: 269 months remaining as of Apr 2026
B32: Current EMI (₹/mo) | C32: 57328 | D32: Exact EMI ₹57,328 — debited 15th every month
B33: MF Current Value (₹) | C33: 1065000 | D33: All 22 funds combined
B34: PPF Balance (₹) | C34: 80000 | D34: Check NRI status
B35: NPS Balance (₹) | C35: 60000 | D35: Tier 1
B36: Emergency FD (₹) | C36: 45000 | D36: Target ₹3L
B37: Monthly SIP Total (₹) | C37: 75000 | D37: 4 funds
B38: FI Corpus Target (₹) | C38: 60000000 | D38: ₹6 Crore
